Error in sys.excepthook:
Traceback (most recent call last):
  File "/home/dyw/miniconda3/envs/xuance_env/lib/python3.8/linecache.py", line 47, in getlines
    return updatecache(filename, module_globals)
  File "/home/dyw/miniconda3/envs/xuance_env/lib/python3.8/linecache.py", line 136, in updatecache
    with tokenize.open(fullname) as fp:
  File "/home/dyw/miniconda3/envs/xuance_env/lib/python3.8/tokenize.py", line 394, in open
    encoding, lines = detect_encoding(buffer.readline)
  File "/home/dyw/miniconda3/envs/xuance_env/lib/python3.8/tokenize.py", line 313, in detect_encoding
    filename = readline.__self__.name
KeyboardInterrupt
Original exception was:
Traceback (most recent call last):
  File "/home/dyw/reinforcement_learning/random-network-distillation-pytorch/eval.py", line 5, in <module>
    agent.testing()
  File "/home/dyw/reinforcement_learning/random-network-distillation-pytorch/train.py", line 264, in testing
    s, r, d, rd, lr = parent_conn.recv()
  File "/home/dyw/miniconda3/envs/xuance_env/lib/python3.8/multiprocessing/connection.py", line 250, in recv
    buf = self._recv_bytes()
  File "/home/dyw/miniconda3/envs/xuance_env/lib/python3.8/multiprocessing/connection.py", line 414, in _recv_bytes
    buf = self._recv(4)
  File "/home/dyw/miniconda3/envs/xuance_env/lib/python3.8/multiprocessing/connection.py", line 379, in _recv
    chunk = read(handle, remaining)
KeyboardInterrupt