2025-06-26 18:05:30,320 INFO    MainThread:3899085 [wandb_setup.py:_flush():76] Current SDK version is 0.15.3
2025-06-26 18:05:30,320 INFO    MainThread:3899085 [wandb_setup.py:_flush():76] Configure stats pid to 3899085
2025-06-26 18:05:30,320 INFO    MainThread:3899085 [wandb_setup.py:_flush():76] Loading settings from /home/dyw/.config/wandb/settings
2025-06-26 18:05:30,320 INFO    MainThread:3899085 [wandb_setup.py:_flush():76] Loading settings from /home/dyw/reinforcement_learning/random-network-distillation-pytorch/wandb/settings
2025-06-26 18:05:30,320 INFO    MainThread:3899085 [wandb_setup.py:_flush():76] Loading settings from environment variables: {}
2025-06-26 18:05:30,320 INFO    MainThread:3899085 [wandb_setup.py:_flush():76] Applying setup settings: {'_disable_service': False}
2025-06-26 18:05:30,320 INFO    MainThread:3899085 [wandb_setup.py:_flush():76] Inferring run settings from compute environment: {'program_relpath': 'train.py', 'program': '/home/dyw/reinforcement_learning/random-network-distillation-pytorch/train.py'}
2025-06-26 18:05:30,320 INFO    MainThread:3899085 [wandb_init.py:_log_setup():507] Logging user logs to ./logs/rnd/wandb/run-20250626_180530-fcznxwhl/logs/debug.log
2025-06-26 18:05:30,320 INFO    MainThread:3899085 [wandb_init.py:_log_setup():508] Logging internal logs to ./logs/rnd/wandb/run-20250626_180530-fcznxwhl/logs/debug-internal.log
2025-06-26 18:05:30,321 INFO    MainThread:3899085 [wandb_init.py:init():547] calling init triggers
2025-06-26 18:05:30,321 INFO    MainThread:3899085 [wandb_init.py:init():554] wandb.init called with sweep_config: {}
config: {'Agent': 'RND', 'EnvType': ['atari'], 'EnvID': 'ALE/MontezumaRevenge-v5', 'Device': 'cuda:2', 'MaxStepPerEpisode': 4500, 'ExtCoef': 2.0, 'MaxStep': 10000000, 'LearningRate': 0.0001, 'NumEnv': 128, 'NumStep': 128, 'Gamma': 0.999, 'IsLoadModel': False, 'IsRender': False, 'IntGamma': 0.99, 'Lambda': 0.95, 'StableEps': '1e-8', 'StateStackSize': 4, 'PreProcHeight': 84, 'ProProcWidth': 84, 'UseGAE': True, 'UseGPU': True, 'UseNorm': False, 'UseNoisyNet': False, 'ClipGradNorm': 0.5, 'ClipRange': 5, 'Entropy': 0.001, 'Epoch': 4, 'MiniBatch': 4, 'PPOEps': 0.1, 'IntCoef': 1.0, 'StickyAction': True, 'ActionProb': 0.25, 'UpdateProportion': 0.25, 'LifeDone': False, 'ObsNormStep': 50, 'Filters': [32, 64, 64], 'Kernels': [8, 4, 3], 'Strides': [4, 2, 1], 'FcHiddenSizes': [512], 'ActorHiddenSizes': [], 'CriticHiddenSizes': [], 'RndPredHiddenSizes': [512, 512], 'RndTargetHiddenSizes': [512], 'ModelPath': 'models/MontezumaRevenge.model', 'PredictorPath': 'models/MontezumaRevenge.pred', 'TargetPath': 'models/MontezumaRevenge.target', 'LogPath': './logs/rnd/', 'WandbUserName': '2036105396-nanjing-university', 'ProjectName': 'RND_MontezunmaRevenge'}
2025-06-26 18:05:30,321 INFO    MainThread:3899085 [wandb_init.py:init():596] starting backend
2025-06-26 18:05:30,321 INFO    MainThread:3899085 [wandb_init.py:init():600] setting up manager
2025-06-26 18:05:30,325 INFO    MainThread:3899085 [backend.py:_multiprocessing_setup():106] multiprocessing start_methods=fork,spawn,forkserver, using: fork
2025-06-26 18:05:30,330 INFO    MainThread:3899085 [wandb_init.py:init():606] backend started and connected
2025-06-26 18:05:30,338 INFO    MainThread:3899085 [wandb_init.py:init():700] updated telemetry
2025-06-26 18:05:30,356 INFO    MainThread:3899085 [wandb_init.py:init():737] communicating run to backend with 60.0 second timeout
2025-06-26 18:06:03,723 INFO    Thread-1  :3899085 [retry.py:__call__():172] Retry attempt failed:
Traceback (most recent call last):
  File "/home/dyw/miniconda3/envs/xuance_env/lib/python3.8/site-packages/urllib3/connection.py", line 199, in _new_conn
    sock = connection.create_connection(
  File "/home/dyw/miniconda3/envs/xuance_env/lib/python3.8/site-packages/urllib3/util/connection.py", line 85, in create_connection
    raise err
  File "/home/dyw/miniconda3/envs/xuance_env/lib/python3.8/site-packages/urllib3/util/connection.py", line 73, in create_connection
    sock.connect(sa)
socket.timeout: timed out

The above exception was the direct cause of the following exception:

Traceback (most recent call last):
  File "/home/dyw/miniconda3/envs/xuance_env/lib/python3.8/site-packages/urllib3/connectionpool.py", line 789, in urlopen
    response = self._make_request(
  File "/home/dyw/miniconda3/envs/xuance_env/lib/python3.8/site-packages/urllib3/connectionpool.py", line 490, in _make_request
    raise new_e
  File "/home/dyw/miniconda3/envs/xuance_env/lib/python3.8/site-packages/urllib3/connectionpool.py", line 466, in _make_request
    self._validate_conn(conn)
  File "/home/dyw/miniconda3/envs/xuance_env/lib/python3.8/site-packages/urllib3/connectionpool.py", line 1095, in _validate_conn
    conn.connect()
  File "/home/dyw/miniconda3/envs/xuance_env/lib/python3.8/site-packages/urllib3/connection.py", line 693, in connect
    self.sock = sock = self._new_conn()
  File "/home/dyw/miniconda3/envs/xuance_env/lib/python3.8/site-packages/urllib3/connection.py", line 208, in _new_conn
    raise ConnectTimeoutError(
urllib3.exceptions.ConnectTimeoutError: (<urllib3.connection.HTTPSConnection object at 0x73c2941038e0>, 'Connection to api.wandb.ai timed out. (connect timeout=10)')

The above exception was the direct cause of the following exception:

Traceback (most recent call last):
  File "/home/dyw/miniconda3/envs/xuance_env/lib/python3.8/site-packages/requests/adapters.py", line 667, in send
    resp = conn.urlopen(
  File "/home/dyw/miniconda3/envs/xuance_env/lib/python3.8/site-packages/urllib3/connectionpool.py", line 843, in urlopen
    retries = retries.increment(
  File "/home/dyw/miniconda3/envs/xuance_env/lib/python3.8/site-packages/urllib3/util/retry.py", line 519, in increment
    raise MaxRetryError(_pool, url, reason) from reason  # type: ignore[arg-type]
urllib3.exceptions.MaxRetryError: HTTPSConnectionPool(host='api.wandb.ai', port=443): Max retries exceeded with url: /graphql (Caused by ConnectTimeoutError(<urllib3.connection.HTTPSConnection object at 0x73c2941038e0>, 'Connection to api.wandb.ai timed out. (connect timeout=10)'))

During handling of the above exception, another exception occurred:

Traceback (most recent call last):
  File "/home/dyw/miniconda3/envs/xuance_env/lib/python3.8/site-packages/wandb/sdk/lib/retry.py", line 131, in __call__
    result = self._call_fn(*args, **kwargs)
  File "/home/dyw/miniconda3/envs/xuance_env/lib/python3.8/site-packages/wandb/sdk/internal/internal_api.py", line 285, in execute
    return self.client.execute(*args, **kwargs)  # type: ignore
  File "/home/dyw/miniconda3/envs/xuance_env/lib/python3.8/site-packages/wandb/vendor/gql-0.2.0/wandb_gql/client.py", line 52, in execute
    result = self._get_result(document, *args, **kwargs)
  File "/home/dyw/miniconda3/envs/xuance_env/lib/python3.8/site-packages/wandb/vendor/gql-0.2.0/wandb_gql/client.py", line 60, in _get_result
    return self.transport.execute(document, *args, **kwargs)
  File "/home/dyw/miniconda3/envs/xuance_env/lib/python3.8/site-packages/wandb/sdk/lib/gql_request.py", line 55, in execute
    request = self.session.post(self.url, **post_args)
  File "/home/dyw/miniconda3/envs/xuance_env/lib/python3.8/site-packages/requests/sessions.py", line 637, in post
    return self.request("POST", url, data=data, json=json, **kwargs)
  File "/home/dyw/miniconda3/envs/xuance_env/lib/python3.8/site-packages/requests/sessions.py", line 589, in request
    resp = self.send(prep, **send_kwargs)
  File "/home/dyw/miniconda3/envs/xuance_env/lib/python3.8/site-packages/requests/sessions.py", line 703, in send
    r = adapter.send(request, **kwargs)
  File "/home/dyw/miniconda3/envs/xuance_env/lib/python3.8/site-packages/requests/adapters.py", line 688, in send
    raise ConnectTimeout(e, request=request)
requests.exceptions.ConnectTimeout: HTTPSConnectionPool(host='api.wandb.ai', port=443): Max retries exceeded with url: /graphql (Caused by ConnectTimeoutError(<urllib3.connection.HTTPSConnection object at 0x73c2941038e0>, 'Connection to api.wandb.ai timed out. (connect timeout=10)'))
2025-06-26 18:06:09,393 WARNING MainThread:3899085 [wandb_init.py:init():1172] interrupted
Traceback (most recent call last):
  File "/home/dyw/miniconda3/envs/xuance_env/lib/python3.8/site-packages/wandb/sdk/wandb_init.py", line 1150, in init
    run = wi.init()
  File "/home/dyw/miniconda3/envs/xuance_env/lib/python3.8/site-packages/wandb/sdk/wandb_init.py", line 740, in init
    result = run_init_handle.wait(
  File "/home/dyw/miniconda3/envs/xuance_env/lib/python3.8/site-packages/wandb/sdk/lib/mailbox.py", line 283, in wait
    found, abandoned = self._slot._get_and_clear(timeout=wait_timeout)
  File "/home/dyw/miniconda3/envs/xuance_env/lib/python3.8/site-packages/wandb/sdk/lib/mailbox.py", line 130, in _get_and_clear
    if self._wait(timeout=timeout):
  File "/home/dyw/miniconda3/envs/xuance_env/lib/python3.8/site-packages/wandb/sdk/lib/mailbox.py", line 126, in _wait
    return self._event.wait(timeout=timeout)
  File "/home/dyw/miniconda3/envs/xuance_env/lib/python3.8/threading.py", line 558, in wait
    signaled = self._cond.wait(timeout)
  File "/home/dyw/miniconda3/envs/xuance_env/lib/python3.8/threading.py", line 306, in wait
    gotit = waiter.acquire(True, timeout)
KeyboardInterrupt
